<?xml version="1.0" encoding="utf-8"?>
<!-- This URDF was automatically created by SolidWorks to URDF Exporter! Originally created by Stephen Brawner (brawner@gmail.com) 
     Commit Version: 1.6.0-4-g7f85cfe  Build Version: 1.6.7995.38578
     For more information, please see http://wiki.ros.org/sw_urdf_exporter -->
<robot
  name="mobile_robot">
  <link name="dummy_link">
  <pose>"0 0 0 0 0 0"</pose>
  </link>
  <joint name="dummy_joint" type="fixed">
    <parent link="dummy_link" />
    <child link="base_link" />
    <origin xyz = "0 0 0" rpy= "0 0 0" />
    <axis xyz = "0 0 0" />
  </joint>
  <link
    name="base_link">
    <inertial>
      <origin
        xyz="-0.00536959074715763 2.25014524108572E-18 0.217177065699251"
        rpy="0 0 0" />
      <mass
        value="30.1147830562474" />
      <inertia
        ixx="0.267982422238061"
        ixy="3.18961658979921E-17"
        ixz="-0.0121132618103098"
        iyy="2.36479314961082"
        iyz="-1.13699162010747E-17"
        izz="2.57216262300582" />
    </inertial>
    <visual>
      <origin
        xyz="0 0 0"
        rpy="0 0 0" />
      <geometry>
        <mesh
          filename="package://mobile_robot/meshes/base_link.STL" />
      </geometry>
      <material
        name="">
        <color
          rgba="0.792156862745098 0.819607843137255 0.933333333333333 1" />
      </material>
    </visual>
    <collision>
      <origin
        xyz="0 0 0"
        rpy="0 0 0" />
      <geometry>
        <mesh
          filename="package://mobile_robot/meshes/base_link.STL" />
      </geometry>
    </collision>
  </link>
  <link
    name="rear_wheel_shaft">
    <inertial>
      <origin
        xyz="5.55111512312578E-17 -1.38777878078145E-17 0.254"
        rpy="0 0 0" />
      <mass
        value="1.02790122650355" />
      <inertia
        ixx="0.0222708703975125"
        ixy="-5.60277001569187E-22"
        ixz="-8.96443202510807E-22"
        iyy="0.0222708703975125"
        iyz="1.14744729921383E-19"
        izz="0.000331023775623048" />
    </inertial>
    <visual>
      <origin
        xyz="0 0 0"
        rpy="0 0 0" />
      <geometry>
        <mesh
          filename="package://mobile_robot/meshes/rear_wheel_shaft.STL" />
      </geometry>
      <material
        name="">
        <color
          rgba="0.792156862745098 0.819607843137255 0.933333333333333 1" />
      </material>
    </visual>
    <collision>
      <origin
        xyz="0 0 0"
        rpy="0 0 0" />
      <geometry>
        <mesh
          filename="package://mobile_robot/meshes/rear_wheel_shaft.STL" />
      </geometry>
    </collision>
  </link>
  <joint
    name="rear_wheel_shaft_joint"
    type="continuous">
    <origin
      xyz="-0.254 -0.254 0.10414"
      rpy="-1.5708 0 0" />
    <parent
      link="base_link" />
    <child
      link="rear_wheel_shaft" />
    <axis
      xyz="0 0 1" />
  </joint>
  <link
    name="rear_right_wheel">
    <inertial>
      <origin
        xyz="5.15331316508494E-09 -7.95165991385183E-09 0.0253999436872035"
        rpy="0 0 0" />
      <mass
        value="0.627305726641923" />
      <inertia
        ixx="0.00204147696517886"
        ixy="4.79054851895501E-10"
        ixz="-4.2698208997363E-11"
        iyy="0.00204148095012536"
        iyz="6.79392526445359E-11"
        izz="0.00389311509621042" />
    </inertial>
    <visual>
      <origin
        xyz="0 0 0"
        rpy="0 0 0" />
      <geometry>
        <mesh
          filename="package://mobile_robot/meshes/rear_right_wheel.STL" />
      </geometry>
      <material
        name="">
        <color
          rgba="0.792156862745098 0.819607843137255 0.933333333333333 1" />
      </material>
    </visual>
    <collision>
      <origin
        xyz="0 0 0"
        rpy="0 0 0" />
      <geometry>
        <mesh
          filename="package://mobile_robot/meshes/rear_right_wheel.STL" />
      </geometry>
    </collision>
  </link>
  <joint
    name="rear_right_wheel_joint"
    type="fixed">
    <origin
      xyz="0 0 0"
      rpy="0 0 0" />
    <parent
      link="rear_wheel_shaft" />
    <child
      link="rear_right_wheel" />
    <axis
      xyz="0 0 0" />
  </joint>
  <link
    name="rear_left_wheel">
    <inertial>
      <origin
        xyz="5.39349970241076E-09 7.79074413315151E-09 -0.0254000563127965"
        rpy="0 0 0" />
      <mass
        value="0.627305726641922" />
      <inertia
        ixx="0.00204148071053849"
        ixy="1.0615236852379E-09"
        ixz="-4.65888979961479E-11"
        iyy="0.00204147720476573"
        iyz="-6.53326387010376E-11"
        izz="0.00389311509621041" />
    </inertial>
    <visual>
      <origin
        xyz="0 0 0"
        rpy="0 0 0" />
      <geometry>
        <mesh
          filename="package://mobile_robot/meshes/rear_left_wheel.STL" />
      </geometry>
      <material
        name="">
        <color
          rgba="0.792156862745098 0.819607843137255 0.933333333333333 1" />
      </material>
    </visual>
    <collision>
      <origin
        xyz="0 0 0"
        rpy="0 0 0" />
      <geometry>
        <mesh
          filename="package://mobile_robot/meshes/rear_left_wheel.STL" />
      </geometry>
    </collision>
  </link>
  <joint
    name="rear_left_wheel_joint"
    type="fixed">
    <origin
      xyz="0 0 0.508"
      rpy="0 0 0" />
    <parent
      link="rear_wheel_shaft" />
    <child
      link="rear_left_wheel" />
    <axis
      xyz="0 0 0" />
  </joint>
  <link
    name="front_right_shaft">
    <inertial>
      <origin
        xyz="-0.0430899587810152 -0.00162292898887284 0.0239485318372451"
        rpy="0 0 0" />
      <mass
        value="0.535359914923846" />
      <inertia
        ixx="0.000838252769830383"
        ixy="-5.04285302841367E-05"
        ixz="-0.000554743528122547"
        iyy="0.00217524757125797"
        iyz="-2.08943179736833E-05"
        izz="0.00151373756430088" />
    </inertial>
    <visual>
      <origin
        xyz="0 0 0"
        rpy="0 0 0" />
      <geometry>
        <mesh
          filename="package://mobile_robot/meshes/front_right_shaft.STL" />
      </geometry>
      <material
        name="">
        <color
          rgba="0.792156862745098 0.819607843137255 0.933333333333333 1" />
      </material>
    </visual>
    <collision>
      <origin
        xyz="0 0 0"
        rpy="0 0 0" />
      <geometry>
        <mesh
          filename="package://mobile_robot/meshes/front_right_shaft.STL" />
      </geometry>
    </collision>
  </link>
  <joint
    name="front_right_shaft_joint"
    type="continuous">
    <origin
      xyz="0.254 -0.1016 0.10414"
      rpy="0 0 1.5708" />
    <parent
      link="base_link" />
    <child
      link="front_right_shaft" />
    <axis
      xyz="0 0 1" />
    <limit
      lower="-3.14"
      upper="3.14"
      effort="10"
      velocity="10000" />
  </joint>
  <link
    name="front_right_wheel">
    <inertial>
      <origin
        xyz="-0.000955983299853636 9.266000994268E-09 0.0253819470341326"
        rpy="0 0 0" />
      <mass
        value="0.627305726641922" />
      <inertia
        ixx="0.00204410073423413"
        ixy="1.68592920576061E-09"
        ixz="-6.96409453575317E-05"
        iyy="0.00204148012514777"
        iyz="-1.52516835754976E-11"
        izz="0.00389049215213273" />
    </inertial>
    <visual>
      <origin
        xyz="0 0 0"
        rpy="0 0 0" />
      <geometry>
        <mesh
          filename="package://mobile_robot/meshes/front_right_wheel.STL" />
      </geometry>
      <material
        name="">
        <color
          rgba="0.792156862745098 0.819607843137255 0.933333333333333 1" />
      </material>
    </visual>
    <collision>
      <origin
        xyz="0 0 0"
        rpy="0 0 0" />
      <geometry>
        <mesh
          filename="package://mobile_robot/meshes/front_right_wheel.STL" />
      </geometry>
    </collision>
  </link>
  <joint
    name="front_right_wheel_joint"
    type="continuous">
    <origin
      xyz="-0.15229 -0.0057359 0"
      rpy="-1.5708 0 -1.5708" />
    <parent
      link="front_right_shaft" />
    <child
      link="front_right_wheel" />
    <axis
      xyz="0.019056 0 0.99982" />
  </joint>
  <link
    name="front_left_shaft">
    <inertial>
      <origin
        xyz="0.04289975377601 -0.00435772630933368 0.0239485642209087"
        rpy="0 0 0" />
      <mass
        value="0.535359728660285" />
      <inertia
        ixx="0.000850046101262467"
        ixy="0.000134804599224858"
        ixz="0.0005522943546741"
        iyy="0.00216345318304651"
        iyz="-5.6101367132104E-05"
        izz="0.0015137371289239" />
    </inertial>
    <visual>
      <origin
        xyz="0 0 0"
        rpy="0 0 0" />
      <geometry>
        <mesh
          filename="package://mobile_robot/meshes/front_left_shaft.STL" />
      </geometry>
      <material
        name="">
        <color
          rgba="0.792156862745098 0.819607843137255 0.933333333333333 1" />
      </material>
    </visual>
    <collision>
      <origin
        xyz="0 0 0"
        rpy="0 0 0" />
      <geometry>
        <mesh
          filename="package://mobile_robot/meshes/front_left_shaft.STL" />
      </geometry>
    </collision>
  </link>
  <joint
    name="front_left_shaft_joint"
    type="continuous">
    <origin
      xyz="0.254 0.1016 0.10414"
      rpy="0 0 1.5708" />
    <parent
      link="base_link" />
    <child
      link="front_left_shaft" />
    <axis
      xyz="0 0 1" />
    <limit
      lower="-3.14"
      upper="3.14"
      effort="10"
      velocity="10000" />
  </joint>
  <link
    name="front_left_wheel">
    <inertial>
      <origin
        xyz="-0.00256689680593014 -9.45913411487531E-09 -0.0252700198156025"
        rpy="0 0 0" />
      <mass
        value="0.627305726641922" />
      <inertia
        ixx="0.0020603888651654"
        ixy="1.95432978665317E-09"
        ixz="0.000186166060736423"
        iyy="0.00204147956802362"
        iyz="-1.17944122889787E-10"
        izz="0.00387420457832561" />
    </inertial>
    <visual>
      <origin
        xyz="0 0 0"
        rpy="0 0 0" />
      <geometry>
        <mesh
          filename="package://mobile_robot/meshes/front_left_wheel.STL" />
      </geometry>
      <material
        name="">
        <color
          rgba="0.792156862745098 0.819607843137255 0.933333333333333 1" />
      </material>
    </visual>
    <collision>
      <origin
        xyz="0 0 0"
        rpy="0 0 0" />
      <geometry>
        <mesh
          filename="package://mobile_robot/meshes/front_left_wheel.STL" />
      </geometry>
    </collision>
  </link>
  <joint
    name="front_left_wheel_joint"
    type="continuous">
    <origin
      xyz="0.15162 -0.015401 0"
      rpy="-1.5708 0 -1.5708" />
    <parent
      link="front_left_shaft" />
    <child
      link="front_left_wheel" />
    <axis
      xyz="0.019056 0 0.99982" />
  </joint>

  <transmission name="trans_front_left_shaft_joint">
  <type>transmission_interface/SimpleTransmission</type>
  <joint name="front_left_shaft_joint">
      <hardwareInterface>hardware_interface/EffortJointInterface</hardwareInterface>
  </joint>
  <actuator name="motor_front_left_shaft_joint">
      <mechanicalReduction>1</mechanicalReduction>
      <hardwareInterface>hardware_interface/EffortJointInterface</hardwareInterface>
  </actuator>
  </transmission>
  <transmission name="trans_front_right_shaft_joint">
  <type>transmission_interface/SimpleTransmission</type>
  <joint name="front_right_shaft_joint">
      <hardwareInterface>hardware_interface/EffortJointInterface</hardwareInterface>
  </joint>
  <actuator name="motor_front_right_shaft_joint">
  <mechanicalReduction>1</mechanicalReduction>
      <hardwareInterface>hardware_interface/EffortJointInterface</hardwareInterface>
  </actuator>
  </transmission>
  <transmission name="trans_rear_wheel_shaft_joint">
  <type>transmission_interface/SimpleTransmission</type>
  <joint name="rear_wheel_shaft_joint">
      <hardwareInterface>hardware_interface/VelocityJointInterface</hardwareInterface>
  </joint>
  <actuator name="motor_rear_wheel_shaft_joint">
      <mechanicalReduction>1</mechanicalReduction>
      <hardwareInterface>hardware_interface/VelocityJointInterface</hardwareInterface>
  </actuator>
  </transmission>
  
</robot>