<?xml version="1.0" ?>
<!-- =================================================================================== -->
<!-- |    This document was autogenerated by xacro from my_robot_integration.xacro     | -->
<!-- |    EDITING THIS FILE BY HAND IS NOT RECOMMENDED                                 | -->
<!-- =================================================================================== -->
<!-- Name your robot here -->
<robot name="mobile_robot">
  <link name="dummy_link">
    <pose>&quot;0 0 0 0 0 0&quot;</pose>
  </link>
  <joint name="dummy_joint" type="fixed">
    <parent link="dummy_link"/>
    <child link="base_link"/>
    <origin rpy="0 0 0" xyz="0 0 0"/>
    <axis xyz="0 0 0"/>
  </joint>
  <link name="base_link">
    <inertial>
      <origin rpy="0 0 0" xyz="-2.25946001565708E-05 -0.062403452272786 0.384573757231794"/>
      <mass value="68.3202619212701"/>
      <inertia ixx="5.37063950715391" ixy="0.000387792418879414" ixz="-0.000150604314056554" iyy="1.55373832744678" iyz="0.0137971211958053" izz="6.78523043610395"/>
    </inertial>
    <visual>
      <origin rpy="0 0 0" xyz="0 0 0"/>
      <geometry>
        <mesh filename="package://mobile_robot/meshes/base_link.STL"/>
      </geometry>
      <material name="">
        <color rgba="1 1 1 1"/>
      </material>
    </visual>
    <collision>
      <origin rpy="0 0 0" xyz="0 0 0"/>
      <geometry>
        <mesh filename="package://mobile_robot/meshes/base_link.STL"/>
      </geometry>
    </collision>
  </link>
  <link name="rear_left_wheel_shaft">
    <inertial>
      <origin rpy="0 0 0" xyz="1.94289029309402E-16 0 -0.1143"/>
      <mass value="0.468481466874382"/>
      <inertia ixx="0.00130973051373093" ixy="2.9315633839274E-20" ixz="-3.91566390856718E-20" iyy="0.00130973051373093" iyz="-1.95783195428359E-20" izz="0.000151122751584338"/>
    </inertial>
    <visual>
      <origin rpy="0 0 0" xyz="0 0 0"/>
      <geometry>
        <mesh filename="package://mobile_robot/meshes/rear_left_wheel_shaft.STL"/>
      </geometry>
      <material name="">
        <color rgba="0 0 1 1"/>
      </material>
    </visual>
    <collision>
      <origin rpy="0 0 0" xyz="0 0 0"/>
      <geometry>
        <mesh filename="package://mobile_robot/meshes/rear_left_wheel_shaft.STL"/>
      </geometry>
    </collision>
  </link>
  <joint name="rear_left_wheel_shaft_joint" type="continuous">
    <origin rpy="-1.5707963267949 0 -1.5707963267949" xyz="0.3556 0.188811295644438 0.28093186544375"/>
    <parent link="base_link"/>
    <child link="rear_left_wheel_shaft"/>
    <axis xyz="0 0 -1"/>
  </joint>
  <link name="rear_left_wheel">
    <inertial>
      <origin rpy="0 0 0" xyz="2.50818507907535E-08 -1.74865122937184E-08 -0.0254189996399616"/>
      <mass value="0.898923461702657"/>
      <inertia ixx="0.00298323347457261" ixy="8.0030845632189E-10" ixz="9.1214044348779E-10" iyy="0.00298323028364196" iyz="1.94630419891131E-09" izz="0.00566998391942397"/>
    </inertial>
    <visual>
      <origin rpy="0 0 0" xyz="0 0 0"/>
      <geometry>
        <mesh filename="package://mobile_robot/meshes/rear_left_wheel.STL"/>
      </geometry>
      <material name="">
        <color rgba="0.909803921568627 0.443137254901961 0.0313725490196078 1"/>
      </material>
    </visual>
    <collision>
      <origin rpy="0 0 0" xyz="0 0 0"/>
      <geometry>
        <mesh filename="package://mobile_robot/meshes/rear_left_wheel.STL"/>
      </geometry>
    </collision>
  </link>
  <joint name="rear_left_wheel_joint" type="fixed">
    <origin rpy="0 0 0" xyz="0 0 0"/>
    <parent link="rear_left_wheel_shaft"/>
    <child link="rear_left_wheel"/>
    <axis xyz="0 0 0"/>
  </joint>
  <link name="rear_right_wheel_shaft">
    <inertial>
      <origin rpy="0 0 0" xyz="-1.94289029309402E-16 -5.55111512312578E-17 0.1143"/>
      <mass value="0.468481466874382"/>
      <inertia ixx="0.00130973051373093" ixy="2.6509049401244E-53" ixz="-1.30522130285573E-20" iyy="0.00130973051373093" iyz="-2.04427928104694E-36" izz="0.000151122751584338"/>
    </inertial>
    <visual>
      <origin rpy="0 0 0" xyz="0 0 0"/>
      <geometry>
        <mesh filename="package://mobile_robot/meshes/rear_right_wheel_shaft.STL"/>
      </geometry>
      <material name="">
        <color rgba="0 0 1 1"/>
      </material>
    </visual>
    <collision>
      <origin rpy="0 0 0" xyz="0 0 0"/>
      <geometry>
        <mesh filename="package://mobile_robot/meshes/rear_right_wheel_shaft.STL"/>
      </geometry>
    </collision>
  </link>
  <joint name="rear_right_wheel_shaft_joint" type="continuous">
    <origin rpy="1.5707963267949 0 1.5707963267949" xyz="-0.3556 0.188811295644438 0.28093186544375"/>
    <parent link="base_link"/>
    <child link="rear_right_wheel_shaft"/>
    <axis xyz="0 0 -1"/>
  </joint>
  <link name="rear_right_wheel">
    <inertial>
      <origin rpy="0 0 0" xyz="-2.50818509017758E-08 1.74865123492296E-08 0.0253810003600383"/>
      <mass value="0.898923461702656"/>
      <inertia ixx="0.00298323347457261" ixy="8.00308453160405E-10" ixz="-9.12140444112547E-10" iyy="0.00298323028364196" iyz="-1.94630419902515E-09" izz="0.00566998391942397"/>
    </inertial>
    <visual>
      <origin rpy="0 0 0" xyz="0 0 0"/>
      <geometry>
        <mesh filename="package://mobile_robot/meshes/rear_right_wheel.STL"/>
      </geometry>
      <material name="">
        <color rgba="0.909803921568627 0.443137254901961 0.0313725490196078 1"/>
      </material>
    </visual>
    <collision>
      <origin rpy="0 0 0" xyz="0 0 0"/>
      <geometry>
        <mesh filename="package://mobile_robot/meshes/rear_right_wheel.STL"/>
      </geometry>
    </collision>
  </link>
  <joint name="rear_right_wheel_joint" type="fixed">
    <origin rpy="0 0 0" xyz="0 0 0"/>
    <parent link="rear_right_wheel_shaft"/>
    <child link="rear_right_wheel"/>
    <axis xyz="0 0 0"/>
  </joint>
  <link name="front_right_wheel_shaft">
    <inertial>
      <origin rpy="0 0 0" xyz="-0.00360185657960171 0.0196805518035527 0.132396071457413"/>
      <mass value="0.662757641502811"/>
      <inertia ixx="0.00251068311249175" ixy="1.61508343182953E-05" ixz="4.56546510107146E-05" iyy="0.0018935373555913" iyz="-0.00059369273981454" izz="0.000833768944559177"/>
    </inertial>
    <visual>
      <origin rpy="0 0 0" xyz="0 0 0"/>
      <geometry>
        <mesh filename="package://mobile_robot/meshes/front_right_wheel_shaft.STL"/>
      </geometry>
      <material name="">
        <color rgba="1 1 1 1"/>
      </material>
    </visual>
    <collision>
      <origin rpy="0 0 0" xyz="0 0 0"/>
      <geometry>
        <mesh filename="package://mobile_robot/meshes/front_right_wheel_shaft.STL"/>
      </geometry>
    </collision>
  </link>
  <joint name="front_right_wheel_shaft_joint" type="revolute">
    <origin rpy="1.5708 0 1.5708" xyz="-0.35553 -0.31435 0.28093"/>
    <parent link="base_link"/>
    <child link="front_right_wheel_shaft"/>
    <axis xyz="1 0 0"/>
    <limit effort="0" lower="0" upper="0" velocity="0"/>
  </joint>
  <transmission name="trans_front_right_wheel_shaft_joint">
    <type>transmission_interface/SimpleTransmission</type>
    <joint name="front_right_wheel_shaft_joint">
      <hardwareInterface>EffortJointInterface</hardwareInterface>
    </joint>
    <actuator name="motor_front_right_wheel_shaft_joint">
      <mechanicalReduction>1</mechanicalReduction>
      <hardwareInterface>EffortJointInterface</hardwareInterface>
    </actuator>
  </transmission>
  <link name="front_right_wheel">
    <inertial>
      <origin rpy="0 0 0" xyz="-0.000690264139604047 1.36018457053133E-08 0.0253716123786964"/>
      <mass value="0.898923461702655"/>
      <inertia ixx="0.00298522024326352" ixy="1.2859664732117E-09" ixz="-7.30398262744775E-05" iyy="0.00298323058601774" iyz="-2.02519461236709E-09" izz="0.00566799684835727"/>
    </inertial>
    <visual>
      <origin rpy="0 0 0" xyz="0 0 0"/>
      <geometry>
        <mesh filename="package://mobile_robot/meshes/front_right_wheel.STL"/>
      </geometry>
      <material name="">
        <color rgba="0.909803921568627 0.443137254901961 0.0313725490196078 1"/>
      </material>
    </visual>
    <collision>
      <origin rpy="0 0 0" xyz="0 0 0"/>
      <geometry>
        <mesh filename="package://mobile_robot/meshes/front_right_wheel.STL"/>
      </geometry>
    </collision>
  </link>
  <joint name="front_right_wheel_joint" type="continuous">
    <origin rpy="0 0 0" xyz="0 0 0"/>
    <parent link="front_right_wheel_shaft"/>
    <child link="front_right_wheel"/>
    <axis xyz="-0.00273683970937426 0 -0.999996254847189"/>
  </joint>
  <transmission name="trans_front_right_wheel_joint">
    <type>transmission_interface/SimpleTransmission</type>
    <joint name="front_right_wheel_joint">
      <hardwareInterface>VelocityJointInterface</hardwareInterface>
    </joint>
    <actuator name="motor_front_right_wheel_joint">
      <mechanicalReduction>1</mechanicalReduction>
      <hardwareInterface>VelocityJointInterface</hardwareInterface>
    </actuator>
  </transmission>
  <link name="front_left_wheel_shaft">
    <inertial>
      <origin rpy="0 0 0" xyz="-0.00505136395318612 0.0196805519337054 -0.132348693989804"/>
      <mass value="0.66275764390845"/>
      <inertia ixx="0.00250948227588092" ixy="2.26520389431454E-05" ixz="-6.40044498645542E-05" iyy="0.00189353737149804" iyz="0.000593480256859154" izz="0.000834969763617833"/>
    </inertial>
    <visual>
      <origin rpy="0 0 0" xyz="0 0 0"/>
      <geometry>
        <mesh filename="package://mobile_robot/meshes/front_left_wheel_shaft.STL"/>
      </geometry>
      <material name="">
        <color rgba="1 1 1 1"/>
      </material>
    </visual>
    <collision>
      <origin rpy="0 0 0" xyz="0 0 0"/>
      <geometry>
        <mesh filename="package://mobile_robot/meshes/front_left_wheel_shaft.STL"/>
      </geometry>
    </collision>
  </link>
  <joint name="front_left_wheel_shaft_joint" type="revolute">
    <origin rpy="1.5708 0 1.5708" xyz="0.35547 -0.31241 0.28093"/>
    <parent link="base_link"/>
    <child link="front_left_wheel_shaft"/>
    <axis xyz="-0.0027368 0 -1"/>
    <limit effort="0" lower="0" upper="0" velocity="0"/>
  </joint>
  <transmission name="trans_front_left_wheel_shaft_joint">
    <type>transmission_interface/SimpleTransmission</type>
    <joint name="front_left_wheel_shaft_joint">
      <hardwareInterface>EffortJointInterface</hardwareInterface>
    </joint>
    <actuator name="motor_front_left_wheel_shaft_joint">
      <mechanicalReduction>1</mechanicalReduction>
      <hardwareInterface>EffortJointInterface</hardwareInterface>
    </actuator>
  </transmission>
  <link name="front_left_wheel">
    <inertial>
      <origin rpy="0 0 0" xyz="-0.000969490827605057 1.74865123492296E-08 -0.0254005045271187"/>
      <mass value="0.898923461702659"/>
      <inertia ixx="0.00298714159238358" ixy="7.2549526952249E-10" ixz="0.000102395624335985" iyy="0.00298323028364196" iyz="-1.97541141777494E-09" izz="0.00566607580161301"/>
    </inertial>
    <visual>
      <origin rpy="0 0 0" xyz="0 0 0"/>
      <geometry>
        <mesh filename="package://mobile_robot/meshes/front_left_wheel.STL"/>
      </geometry>
      <material name="">
        <color rgba="0.909803921568627 0.443137254901961 0.0313725490196078 1"/>
      </material>
    </visual>
    <collision>
      <origin rpy="0 0 0" xyz="0 0 0"/>
      <geometry>
        <mesh filename="package://mobile_robot/meshes/front_left_wheel.STL"/>
      </geometry>
    </collision>
  </link>
  <joint name="front_left_wheel_joint" type="continuous">
    <origin rpy="0 0 0" xyz="0 0 0"/>
    <parent link="front_left_wheel_shaft"/>
    <child link="front_left_wheel"/>
    <axis xyz="-0.00273683970937426 0 -0.999996254847189"/>
  </joint>
  <transmission name="trans_front_left_wheel_joint">
    <type>transmission_interface/SimpleTransmission</type>
    <joint name="front_left_wheel_joint">
      <hardwareInterface>VelocityJointInterface</hardwareInterface>
    </joint>
    <actuator name="motor_front_left_wheel_joint">
      <mechanicalReduction>1</mechanicalReduction>
      <hardwareInterface>VelocityJointInterface</hardwareInterface>
    </actuator>
  </transmission>
  <link name="base_laser">
    <inertial>
      <origin rpy="0 0 0" xyz="-0.00029774 0.0066667 0.00013047"/>
      <mass value="0.15717"/>
      <inertia ixx="6.7885E-05" ixy="-1.3987E-07" ixz="-8.1554E-07" iyy="0.00013173" iyz="-9.0932E-08" izz="7.1972E-05"/>
    </inertial>
    <visual>
      <origin rpy="0 0 0" xyz="0 0 0"/>
      <geometry>
        <mesh filename="package://mobile_robot/meshes/ydlidar.dae"/>
      </geometry>
      <material name="">
        <color rgba="0.64706 0.61961 0.58824 1"/>
      </material>
    </visual>
    <collision>
      <origin rpy="0 0 0" xyz="0 0 0"/>
      <geometry>
        <mesh filename="package://mobile_robot/meshes/ydlidar.dae"/>
      </geometry>
    </collision>
  </link>
  <link name="laser_frame">
    <inertial>
      <origin rpy="0 0 0" xyz="-0.00036659 0.00064155 -0.00027052"/>
      <mass value="0.25482"/>
      <inertia ixx="8.9194E-05" ixy="1.8116E-07" ixz="3.6435E-08" iyy="0.00018279" iyz="2.423E-07" izz="0.00011103"/>
    </inertial>
    <visual>
      <origin rpy="0 0 0" xyz="0 0 0"/>
      <geometry>
        <mesh filename="package://mobile_robot/meshes/ydlidar.dae"/>
      </geometry>
      <material name="">
        <color rgba="0.64706 0.61961 0.58824 1"/>
      </material>
    </visual>
    <collision>
      <origin rpy="0 0 0" xyz="0 0 0"/>
      <geometry>
        <mesh filename="package://mobile_robot/meshes/ydlidar.dae"/>
      </geometry>
    </collision>
  </link>
  <joint name="laser_joint" type="fixed">
    <origin rpy="0 0 0" xyz="0 0 0.03172"/>
    <parent link="base_laser"/>
    <child link="laser_frame"/>
    <axis xyz="0 0 0"/>
  </joint>
  <!-- Add your gazebo sensors here -->
  <gazebo reference="base_laser">
    <!-- <gravity>true</gravity> -->
    <!-- Gazebo has fixed set of Sensors types. Check them out here <> -->
    <sensor name="laser" type="ray">
      <!-- Add in your sensor characteristics -->
      <pose> 0 0 0 0 0 0 </pose>
      <visualise>true</visualise>
      <update_rate>40</update_rate>
      <!-- <always_on>true</always_on> -->
      <ray>
        <scan>
          <horizontal>
            <samples>720</samples>
            <resolution>1</resolution>
            <min_angle>-1.570796</min_angle>
            <max_angle>1.570796</max_angle>
          </horizontal>
        </scan>
        <range>
          <min>0.10</min>
          <max>30.0</max>
          <resolution>0.01</resolution>
        </range>
        <noise>
          <type>gaussian</type>
          <mean>0.0</mean>
          <stddev>0.01</stddev>
        </noise>
      </ray>
      <plugin filename="libgazebo_ros_laser.so" name="gazebo_ros_head_hokuyo_controller">
        <!-- Use topic name as /my_robot/scan -->
        <topicName>/mobile_robot/scan</topicName>
        <frameName>laser_frame</frameName>
      </plugin>
    </sensor>
  </gazebo>
  <!--  Gazebo plugin for control here is already added for you -->
  <gazebo>
    <plugin filename="libgazebo_ros_control.so" name="gazebo_ros_control">
      <robotNamespace>/mobile_robot</robotNamespace>
      <robotSimType>gazebo_ros_control/DefaultRobotHWSim</robotSimType>
      <legacyModeNS>true</legacyModeNS>
    </plugin>
  </gazebo>
  <!-- Create a joint between your robot and sensor 
	  <link name="base_lidar">
  <inertial>
    <origin xyz="0 0 0" rpy="0 0 0"/>
    <mass value="0.125"/>
    <inertia ixx="0.001"  ixy="0"  ixz="0" iyy="0.001" iyz="0" izz="0.001" />
  </inertial>

  <collision>
    <origin xyz="0 0 0" rpy="0 0 0"/>
    <geometry>
       <cylinder radius="0.0508" length="0.055"/>
    </geometry>
  </collision>

  <visual>
    <origin xyz="0 0 0" rpy="0 0 0"/>
    <geometry>
       <cylinder radius="0.0508" length="0.055"/>
    </geometry>
  </visual>
</link>-->
  <joint name="lidar_joint" type="fixed">
    <parent link="base_link"/>
    <child link="base_laser"/>
    <origin rpy="0 0 0" xyz="0 0 0.35"/>
  </joint>
</robot>
